<mujoco model="reacher">
  <compiler angle="radian" inertiafromgeom="true"/>
  <default>
    <joint armature="1" damping="1" limited="true"/>
    <geom contype="0" friction="1 0.1 0.1" rgba="0.7 0.7 0 1"/>
  </default>
  <option gravity="0 0 -9.81" integrator="RK4" timestep="0.01"/>
  <worldbody>
    <!-- Arena -->
    <geom type="plane" size="1 1 10" rgba="0.9 0.9 0.9 1" pos="0 0 0"/>
    <geom fromto="-.3 -.3 .01 .3 -.3 .01" name="sideS" rgba="0.9 0.4 0.6 1" size=".02" type="capsule"/>
    <geom fromto=" .3 -.3 .01 .3  .3 .01" name="sideE" rgba="0.9 0.4 0.6 1" size=".02" type="capsule"/>
    <geom fromto="-.3  .3 .01 .3  .3 .01" name="sideN" rgba="0.9 0.4 0.6 1" size=".02" type="capsule"/>
    <geom fromto="-.3 -.3 .01 -.3 .3 .01" name="sideW" rgba="0.9 0.4 0.6 1" size=".02" type="capsule"/>
    
    <!-- Arm -->
    <geom fromto="0 0 0 0 0 0.02" name="root" rgba="0.9 0.4 0.6 1" size=".011" type="cylinder"/>
    <body name="body0" pos="0 0 0.01">
      <geom fromto="0 0 0 0.1 0 0" name="link0" rgba="0.0 0.4 0.6 1" size=".01" type="capsule"/>
      <joint name="joint0" type="hinge" axis="0 0 1" pos="0 0 0" limited="false"/>
      <body name="body1" pos="0.1 0 0">
        <joint name="joint1" type="hinge" axis="0 0 1" pos="0 0 0" range="-3.0 3.0" limited="true"/>
        <geom fromto="0 0 0 0.1 0 0" name="link1" rgba="0.0 0.4 0.6 1" size=".01" type="capsule"/>
        <body name="fingertip" pos="0.11 0 0">
          <geom name="fingertip_geom" type="sphere" pos="0 0 0" size=".01" rgba="0.0 0.8 0.6 1" contype="0"/>
          <site name="fingertip" pos="0 0 0" size="0.005" rgba="0 1 0 1"/>
        </body>
      </body>
    </body>
    
    <!-- Movable Red Ball Object -->
    <body name="object_body" pos="0 0 0.01">
      <joint name="target1_x" type="slide" axis="1 0 0" pos="0 0 0" range="-0.13 0.13"/>
      <joint name="target1_y" type="slide" axis="0 1 0" pos="0 0 0" range="-0.13 0.13"/>
      <geom name="object_geom" type="sphere" pos="0 0 0" size="0.02" mass="0.00001" rgba="1 0 0 1" contype="1"/>
      <site name="target1_site" pos="0 0 0" size="0.005" rgba="1 0 0 1"/>
    </body>

    <body name="target_body" pos="-0.16 0.1 0.01">
      <joint name="target2_x" type="slide" axis="1 0 0" pos="0 0 0" range="-0.27 0.27"/>
      <joint name="target2_y" type="slide" axis="0 1 0" pos="0 0 0" range="-0.27 0.27"/>
      <geom name="target_geom" type="sphere" pos="0 0 0" size="0.02" mass="0.00001" rgba="0 1 0 1" contype="0"/>
      <site name="target2_site" pos="0 0 0" size="0.005" rgba="0 1 0 1"/>
    </body>


    
  </worldbody>
  
  <actuator>
    <motor joint="joint0" ctrllimited="true" ctrlrange="-1.0 1.0" gear="200.0"/>
    <motor joint="joint1" ctrllimited="true" ctrlrange="-1.0 1.0" gear="200.0"/>
  </actuator>
</mujoco>
